[2021-10-29 16:06:53] [ ERROR] [App:47] Regra de chave primaria unica violada!
org.h2.jdbc.JdbcSQLIntegrityConstraintViolationException: Unique index or primary key violation: "PRIMARY KEY ON PUBLIC.FUNCIONARIOS(ID) [1, 'Joao', 'Silva', 23]"; SQL statement:
INSERT INTO funcionarios (id, nome, sobrenome, idade) VALUES (1, 'Davi', 'Santos', 33); [23505-200]
	at org.h2.message.DbException.getJdbcSQLException(DbException.java:459)
	at org.h2.message.DbException.getJdbcSQLException(DbException.java:429)
	at org.h2.message.DbException.get(DbException.java:205)
	at org.h2.message.DbException.get(DbException.java:181)
	at org.h2.mvstore.db.MVPrimaryIndex.add(MVPrimaryIndex.java:127)
	at org.h2.mvstore.db.MVTable.addRow(MVTable.java:531)
	at org.h2.command.dml.Insert.insertRows(Insert.java:195)
	at org.h2.command.dml.Insert.update(Insert.java:151)
	at org.h2.command.CommandContainer.update(CommandContainer.java:198)
	at org.h2.command.Command.executeUpdate(Command.java:251)
	at org.h2.jdbc.JdbcStatement.executeInternal(JdbcStatement.java:228)
	at org.h2.jdbc.JdbcStatement.execute(JdbcStatement.java:201)
	at App.main(App.java:40)
[2021-10-29 16:06:53] [ INFO ] [App:54] Conexao com o banco de dados encerrada!!
[2021-10-29 16:14:57] [ ERROR] [App:53] A conexao com o banco de dados falhou!
org.h2.jdbc.JdbcSQLNonTransientConnectionException: Database may be already in use: null. Possible solutions: close all other connection(s); use the server mode [90020-200]
	at org.h2.message.DbException.getJdbcSQLException(DbException.java:622)
	at org.h2.message.DbException.getJdbcSQLException(DbException.java:429)
	at org.h2.message.DbException.get(DbException.java:194)
	at org.h2.mvstore.db.MVTableEngine$Store.convertIllegalStateException(MVTableEngine.java:206)
	at org.h2.mvstore.db.MVTableEngine$Store.open(MVTableEngine.java:182)
	at org.h2.mvstore.db.MVTableEngine.init(MVTableEngine.java:103)
	at org.h2.engine.Database.getPageStore(Database.java:2659)
	at org.h2.engine.Database.open(Database.java:675)
	at org.h2.engine.Database.openDatabase(Database.java:307)
	at org.h2.engine.Database.<init>(Database.java:301)
	at org.h2.engine.Engine.openSession(Engine.java:74)
	at org.h2.engine.Engine.openSession(Engine.java:192)
	at org.h2.engine.Engine.createSessionAndValidate(Engine.java:171)
	at org.h2.engine.Engine.createSession(Engine.java:166)
	at org.h2.engine.Engine.createSession(Engine.java:29)
	at org.h2.engine.SessionRemote.connectEmbeddedOrServer(SessionRemote.java:340)
	at org.h2.jdbc.JdbcConnection.<init>(JdbcConnection.java:173)
	at org.h2.jdbc.JdbcConnection.<init>(JdbcConnection.java:152)
	at org.h2.Driver.connect(Driver.java:69)
	at java.sql/java.sql.DriverManager.getConnection(DriverManager.java:677)
	at java.sql/java.sql.DriverManager.getConnection(DriverManager.java:228)
	at App.getConnection(App.java:30)
	at App.main(App.java:37)
Caused by: java.lang.IllegalStateException: The file is locked: nio:/home/aloisiot/test.mv.db [1.4.200/7]
	at org.h2.mvstore.DataUtils.newIllegalStateException(DataUtils.java:950)
	at org.h2.mvstore.FileStore.open(FileStore.java:172)
	at org.h2.mvstore.MVStore.<init>(MVStore.java:381)
	at org.h2.mvstore.MVStore$Builder.open(MVStore.java:3579)
	at org.h2.mvstore.db.MVTableEngine$Store.open(MVTableEngine.java:170)
	... 18 more
[2021-10-29 16:15:27] [ INFO ] [App:46] Usuarios inseridos com sucesso!!
[2021-10-29 16:15:27] [ INFO ] [App:57] Conexao com o banco de dados encerrada!!
[2021-10-29 16:18:06] [ ERROR] [App:57] A conexao com o banco de dados falhou!
org.h2.jdbc.JdbcSQLNonTransientConnectionException: Database may be already in use: null. Possible solutions: close all other connection(s); use the server mode [90020-200]
	at org.h2.message.DbException.getJdbcSQLException(DbException.java:622)
	at org.h2.message.DbException.getJdbcSQLException(DbException.java:429)
	at org.h2.message.DbException.get(DbException.java:194)
	at org.h2.mvstore.db.MVTableEngine$Store.convertIllegalStateException(MVTableEngine.java:206)
	at org.h2.mvstore.db.MVTableEngine$Store.open(MVTableEngine.java:182)
	at org.h2.mvstore.db.MVTableEngine.init(MVTableEngine.java:103)
	at org.h2.engine.Database.getPageStore(Database.java:2659)
	at org.h2.engine.Database.open(Database.java:675)
	at org.h2.engine.Database.openDatabase(Database.java:307)
	at org.h2.engine.Database.<init>(Database.java:301)
	at org.h2.engine.Engine.openSession(Engine.java:74)
	at org.h2.engine.Engine.openSession(Engine.java:192)
	at org.h2.engine.Engine.createSessionAndValidate(Engine.java:171)
	at org.h2.engine.Engine.createSession(Engine.java:166)
	at org.h2.engine.Engine.createSession(Engine.java:29)
	at org.h2.engine.SessionRemote.connectEmbeddedOrServer(SessionRemote.java:340)
	at org.h2.jdbc.JdbcConnection.<init>(JdbcConnection.java:173)
	at org.h2.jdbc.JdbcConnection.<init>(JdbcConnection.java:152)
	at org.h2.Driver.connect(Driver.java:69)
	at java.sql/java.sql.DriverManager.getConnection(DriverManager.java:677)
	at java.sql/java.sql.DriverManager.getConnection(DriverManager.java:228)
	at App.getConnection(App.java:30)
	at App.main(App.java:37)
Caused by: java.lang.IllegalStateException: The file is locked: nio:/home/aloisiot/test.mv.db [1.4.200/7]
	at org.h2.mvstore.DataUtils.newIllegalStateException(DataUtils.java:950)
	at org.h2.mvstore.FileStore.open(FileStore.java:172)
	at org.h2.mvstore.MVStore.<init>(MVStore.java:381)
	at org.h2.mvstore.MVStore$Builder.open(MVStore.java:3579)
	at org.h2.mvstore.db.MVTableEngine$Store.open(MVTableEngine.java:170)
	... 18 more
[2021-10-29 16:18:27] [ DEBUG] [App:45] ID atualizado com sucesso!
[2021-10-29 16:18:27] [ INFO ] [App:50] Usuarios inseridos com sucesso!!
[2021-10-29 16:18:27] [ INFO ] [App:61] Conexao com o banco de dados encerrada!!
[2021-10-29 16:19:32] [ DEBUG] [App:45] 
ID atualizado com sucesso!
[2021-10-29 16:19:32] [ INFO ] [App:50] 
Usuarios inseridos com sucesso!!
[2021-10-29 16:19:32] [ INFO ] [App:61] 
Conexao com o banco de dados encerrada!!
[2021-10-29 16:32:15] [ DEBUG] [App:45] ID atualizado com sucesso!
[2021-10-29 16:32:15] [ INFO ] [App:50] Usuarios inseridos com sucesso!!
[2021-10-29 16:32:15] [ INFO ] [App:61] Conexao com o banco de dados encerrada!!
